<!DOCTYPE html>
<html lang="ko">
<head>
    <meta charset="UTF-8">
    <meta name="viewport" content="width=device-width, initial-scale=1.0">
    <title>promise reject</title>
</head>
<body>
    <h1>promise reject</h1>
    <p>promise reject는 예외처리를 하기 위해 존재한다.(reject는 잘 사용되지 않음: 코드가 복잡하고 promise를 async 함수로 대체할 때 reject가 동작하지 않는다.)</p>
    <!-- async 함수를 더 많이 사용하며 reject는 promise에서만 동작한다. -->
    
    <script>
        new Promise((resolve,reject)=>{
            setTimeout(()=>{
                let result=confirm("확인하면 resolve, 취소하면 reject 실행");
                (result)? resolve() : reject();
            },2000)
        }).then(()=>{
            // resolve를 실행하면 실행되는 콜백함수
            // alert("첫번째 콜백함수")
        },()=>{
            // reject를 실행하면 실행되는 콜백함수
            // alert("두번째 콜백함수")
        })
    </script>

    <h2>Promise.catch 로 위임된 예외를 처리하자</h2>
    <p>Promise가 실행하는 콜백함수에서 오류가 발생하면 굳이 reject 없이 마지막의 콜백함수 catch가 예외처리 가능하다. 하지만 콜백함수 내부에서 예외 처리한 경우 throw로 예외 위임을 해야 Promise.catch가 실행된다.</p>
    <p>throw e로 reject(e)를 대신할 수 있다.</p>
    <p>then(()=>{},()=>{}) : reject가 실행하는 두번째 콜백함수가 없으면 마지막에 작성된 catch가 실행된다.</p>
    
    <script>
        // Promise.catch 예시
        new Promise((resolve)=>{
            let str="{key:13}"; // key가 문자열이 아니라서 오류 발생
            let obj=JSON.parse(str);
            resolve(obj);
        }).catch((e)=>{ // catch가 오류 잡음
            alert(e+"오류발생"); // 오류내역 : SyntaxError
        })


        // throw 예시 - throw new SyntaxError()
        new Promise((resolve)=>{
            let str="{key:13}"; // key가 문자열이 아니라서 오류 발생
            try{
                let obj=JSON.parse(str);
                resolve(obj);
            }catch(e){
                // try catch로 오류 잡는데
                throw e; // catch로 오류 위임
            }
        }).catch((e)=>{ // catch에서 오류 위임하고자 할 때 => throw e
            alert(e+"오류발생");
        })

        
        // reject도 실행, catch도 실행 => 불가... 하나만 사용 가능
        new Promise((resolve,reject)=>{
            let str="{key:13}";
            try{
                let obj=JSON.parse(str);
                resolve(obj);
            }catch(e){
                throw e; // == reject
                // reject(new Error());
            }
        }).then(()=>{},(e)=>{
            alert("reject가 두번째 콜백 실행"+e)
        }).catch((e)=>{
            alert(e+"오류발생");
        })
    </script>
    
</body>
</html>